<?xml version='1.0'?>
<sdf version='1.5'>
  <model name='BlueRov2'>
    <pose>0 0 0 0 0 0</pose>
    <link name='base_link'>
      <inertial>
        <mass>11</mass>
        <inertia>
          <ixx>1</ixx>
          <ixy>0</ixy>
          <ixz>0</ixz>
          <iyy>1</iyy>
          <iyz>0</iyz>
          <izz>1</izz>
        </inertia>
      </inertial>
      <visual name='base_link_visual'>
        <geometry>
          <mesh>
            <scale>1 1 1</scale>
            <uri>model://BlueRov2/meshes/BlueRov2.dae</uri>
          </mesh>
        </geometry>
      </visual>
      <sensor name="imu_sensor" type="imu">
        <pose>0 0 0 0 0 0</pose>
        <always_on>1</always_on>
        <update_rate>1000.0</update_rate>
      </sensor>
    </link>

    <link name='thruster1'>
      <pose>0.064 0.102 0.014 -3.142 -0.838 -3.142</pose>
      <visual name="cil">
        <geometry>
          <mesh>
            <scale>1 1 1</scale>
            <uri>model://BlueRov2/meshes/T200_Prop_CCW.dae</uri>
          </mesh>
        </geometry>
      </visual>
      <inertial>
        <mass>1e-10</mass>
        <inertia>
          <ixx>1</ixx>
          <ixy>0</ixy>
          <ixz>0</ixz>
          <iyy>1</iyy>
          <iyz>0</iyz>
          <izz>1</izz>
        </inertia>
      </inertial>
    </link>
    <joint name='thruster1_joint' type='revolute'>
      <parent>base_link</parent>
      <child>thruster1</child>
      <pose frame=''>0 0 0 0 0 0</pose>
      <axis>
        <xyz>0 0 1</xyz>
        <use_parent_model_frame>0</use_parent_model_frame>
      </axis>
    </joint>

    <link name='thruster2'>
      <pose>0.255 0.102 0.014 -3.142 0.838 -3.142</pose>
      <visual name="cil">
        <geometry>
          <mesh>
            <scale>1 1 1</scale>
            <uri>model://BlueRov2/meshes/T200_Prop_CCW.dae</uri>
          </mesh>
        </geometry>
      </visual>
      <inertial>
        <mass>1e-10</mass>
        <inertia>
          <ixx>1</ixx>
          <ixy>0</ixy>
          <ixz>0</ixz>
          <iyy>1</iyy>
          <iyz>0</iyz>
          <izz>1</izz>
        </inertia>
      </inertial>
    </link>
    <joint name='thruster2_joint' type='revolute'>
      <parent>base_link</parent>
      <child>thruster2</child>
      <pose frame=''>0 0 0 0 0 0</pose>
      <axis>
        <xyz>0 0 1</xyz>
        <use_parent_model_frame>0</use_parent_model_frame>
      </axis>
    </joint>

    <link name='thruster3'>
      <pose>0.066 0.102 -0.28 0 -0.838 0</pose>
      <visual name="cil">
        <geometry>
          <mesh>
            <scale>1 1 1</scale>
            <uri>model://BlueRov2/meshes/T200_Prop_CW.dae</uri>
          </mesh>
        </geometry>
      </visual>
      <inertial>
        <mass>1e-10</mass>
        <inertia>
          <ixx>1</ixx>
          <ixy>0</ixy>
          <ixz>0</ixz>
          <iyy>1</iyy>
          <iyz>0</iyz>
          <izz>1</izz>
        </inertia>
      </inertial>
    </link>
    <joint name='thruster3_joint' type='revolute'>
      <parent>base_link</parent>
      <child>thruster3</child>
      <pose frame=''>0 0 0 0 0 0</pose>
      <axis>
        <xyz>0 0 1</xyz>
        <use_parent_model_frame>0</use_parent_model_frame>
      </axis>
    </joint>

    <link name='thruster4'>
      <pose>0.253 0.102 -0.28 0 0.838 0</pose>
      <visual name="cil">
        <geometry>
          <mesh>
            <scale>1 1 1</scale>
            <uri>model://BlueRov2/meshes/T200_Prop_CW.dae</uri>
          </mesh>
        </geometry>
      </visual>
      <inertial>
        <mass>1e-10</mass>
        <inertia>
          <ixx>1</ixx>
          <ixy>0</ixy>
          <ixz>0</ixz>
          <iyy>1</iyy>
          <iyz>0</iyz>
          <izz>1</izz>
        </inertia>
      </inertial>
    </link>
    <joint name='thruster4_joint' type='revolute'>
      <parent>base_link</parent>
      <child>thruster4</child>
      <pose frame=''>0 0 0 0 0 0</pose>
      <axis>
        <xyz>0 0 1</xyz>
        <use_parent_model_frame>0</use_parent_model_frame>
      </axis>
    </joint>

    <link name='thruster5'>
      <pose>0.049 0.179 -0.125 0 -1.571 1.571</pose>
      <visual name="cil">
        <geometry>
          <mesh>
            <scale>1 1 1</scale>
            <uri>model://BlueRov2/meshes/T200_Prop_CCW.dae</uri>
          </mesh>
        </geometry>
      </visual>
      <inertial>
        <mass>1e-10</mass>
        <inertia>
          <ixx>1</ixx>
          <ixy>0</ixy>
          <ixz>0</ixz>
          <iyy>1</iyy>
          <iyz>0</iyz>
          <izz>1</izz>
        </inertia>
      </inertial>
    </link>
    <joint name='thruster5_joint' type='revolute'>
      <parent>base_link</parent>
      <child>thruster5</child>
      <pose frame=''>0 0 0 0 0 0</pose>
      <axis>
        <xyz>0 0 1</xyz>
        <use_parent_model_frame>0</use_parent_model_frame>
      </axis>
    </joint>

    <link name='thruster6'>
      <pose>0.27 0.179 -0.125 0 1.571 -1.571</pose>
      <visual name="cil">
        <geometry>
          <mesh>
            <scale>1 1 1</scale>
            <uri>model://BlueRov2/meshes/T200_Prop_CW.dae</uri>
          </mesh>
        </geometry>
      </visual>
      <inertial>
        <mass>1e-10</mass>
        <inertia>
          <ixx>1</ixx>
          <ixy>0</ixy>
          <ixz>0</ixz>
          <iyy>1</iyy>
          <iyz>0</iyz>
          <izz>1</izz>
        </inertia>
      </inertial>
    </link>
    <joint name='thruster6_joint' type='revolute'>
      <parent>base_link</parent>
      <child>thruster6</child>
      <pose frame=''>0 0 0 0 0 0</pose>
      <axis>
        <xyz>0 0 1</xyz>
        <use_parent_model_frame>0</use_parent_model_frame>
      </axis>
    </joint>

    <plugin name='prop1_blade_1' filename='libLiftDragPlugin.so'>
      <a0>0.08727</a0>
      <cla>5.418</cla>
      <cda>0.0</cda>
      <alpha_stall>0.3368</alpha_stall>
      <cla_stall>0.0</cla_stall>
      <cda_stall>0.0</cda_stall>
      <area>0.002</area>
      <air_density>1000</air_density>

      <cp>-0.015 0.024 0.005</cp>
      <forward>0.04 0.021 -0.023</forward>
      <upward>-0.019 -0.017 -0.034</upward>
      <link_name>thruster1</link_name>
    </plugin>

    <plugin name='prop1_blade_2' filename='libLiftDragPlugin.so'>
      <a0>0.4</a0>
      <cla>4.752798721</cla>
      <cda>0.6417112299</cda>
      <alpha_stall>1.5</alpha_stall>
      <cla_stall>-3.85</cla_stall>
      <cda_stall>-0.9233984055</cda_stall>
      <area>0.002</area>
      <air_density>1000</air_density>

      <cp>-0.013 -0.025 0.005</cp>
      <forward>-0.038 0.023 -0.023</forward>
      <upward>0.024 -0.008 -0.034</upward>
      <link_name>thruster1</link_name>
    </plugin>

    <plugin name='prop1_blade_3' filename='libLiftDragPlugin.so'>
      <a0>0.4</a0>
      <cla>4.752798721</cla>
      <cda>0.6417112299</cda>
      <alpha_stall>1.5</alpha_stall>
      <cla_stall>-3.85</cla_stall>
      <cda_stall>-0.9233984055</cda_stall>
      <area>0.002</area>
      <air_density>1000</air_density>

      <cp>0.028 0.001 0.005</cp>
      <forward>-0.001 -0.045 -0.023</forward>
      <upward>-0.005 0.025 -0.034</upward>
      <link_name>thruster1</link_name>
    </plugin>

    <plugin name='prop2_blade_1' filename='libLiftDragPlugin.so'>
      <a0>0.08727</a0>
      <cla>5.418</cla>
      <cda>0.0</cda>
      <alpha_stall>0.3368</alpha_stall>
      <cla_stall>0.0</cla_stall>
      <cda_stall>0.0</cda_stall>
      <area>0.002</area>
      <air_density>1000</air_density>

      <cp>-0.015 0.024 0.005</cp>
      <forward>0.04 0.021 -0.023</forward>
      <upward>-0.019 -0.017 -0.034</upward>
      <link_name>thruster2</link_name>
    </plugin>

    <plugin name='prop2_blade_2' filename='libLiftDragPlugin.so'>
      <a0>0.4</a0>
      <cla>4.752798721</cla>
      <cda>0.6417112299</cda>
      <alpha_stall>1.5</alpha_stall>
      <cla_stall>-3.85</cla_stall>
      <cda_stall>-0.9233984055</cda_stall>
      <area>0.002</area>
      <air_density>1000</air_density>

      <cp>-0.013 -0.025 0.005</cp>
      <forward>-0.038 0.023 -0.023</forward>
      <upward>0.024 -0.008 -0.034</upward>
      <link_name>thruster2</link_name>
    </plugin>

    <plugin name='prop2_blade_3' filename='libLiftDragPlugin.so'>
      <a0>0.4</a0>
      <cla>4.752798721</cla>
      <cda>0.6417112299</cda>
      <alpha_stall>1.5</alpha_stall>
      <cla_stall>-3.85</cla_stall>
      <cda_stall>-0.9233984055</cda_stall>
      <area>0.002</area>
      <air_density>1000</air_density>

      <cp>0.028 0.001 0.005</cp>
      <forward>-0.001 -0.045 -0.023</forward>
      <upward>-0.005 0.025 -0.034</upward>
      <link_name>thruster2</link_name>
    </plugin>

    <plugin name='prop3_blade_1' filename='libLiftDragPlugin.so'>
      <a0>0.08727</a0>
      <cla>5.418</cla>
      <cda>0.0</cda>
      <alpha_stall>0.3368</alpha_stall>
      <cla_stall>0.0</cla_stall>
      <cda_stall>0.0</cda_stall>
      <area>0.002</area>
      <air_density>1000</air_density>

      <cp>-0.013001 0.024612 0.0054</cp>
      <forward>-0.17746 -0.10243 -0.0575</forward>
      <upward>0.07209 0.02292 -0.10235</upward>
      <link_name>thruster3</link_name>
    </plugin>

    <plugin name='prop3_blade_2' filename='libLiftDragPlugin.so'>
      <a0>0.4</a0>
      <cla>4.752798721</cla>
      <cda>0.6417112299</cda>
      <alpha_stall>1.5</alpha_stall>
      <cla_stall>-3.85</cla_stall>
      <cda_stall>-0.9233984055</cda_stall>
      <area>0.002</area>
      <air_density>1000</air_density>

      <cp>0.027815 -0.001047 0.0054</cp>
      <forward>0.00002 0.2049 -0.0575</forward>
      <upward>-0.01619 -0.07389 -0.10235</upward>
      <link_name>thruster3</link_name>
    </plugin>

    <plugin name='prop3_blade_3' filename='libLiftDragPlugin.so'>
      <a0>0.4</a0>
      <cla>4.752798721</cla>
      <cda>0.6417112299</cda>
      <alpha_stall>1.5</alpha_stall>
      <cla_stall>-3.85</cla_stall>
      <cda_stall>-0.9233984055</cda_stall>
      <area>0.002</area>
      <air_density>1000</air_density>

      <cp>-0.014814 -0.023565 0.0054</cp>
      <forward>0.17744 -0.10247 -0.05749</forward>
      <upward>-0.0559 0.05097 -0.10235</upward>
      <link_name>thruster3</link_name>
    </plugin>

    <plugin name='prop4_blade_1' filename='libLiftDragPlugin.so'>
      <a0>0.08727</a0>
      <cla>5.418</cla>
      <cda>0.0</cda>
      <alpha_stall>0.3368</alpha_stall>
      <cla_stall>0.0</cla_stall>
      <cda_stall>0.0</cda_stall>
      <area>0.002</area>
      <air_density>1000</air_density>

      <cp>-0.013001 0.024612 0.0054</cp>
      <forward>-0.17746 -0.10243 -0.0575</forward>
      <upward>0.07209 0.02292 -0.10235</upward>
      <link_name>thruster4</link_name>
    </plugin>

    <plugin name='prop4_blade_2' filename='libLiftDragPlugin.so'>
      <a0>0.4</a0>
      <cla>4.752798721</cla>
      <cda>0.6417112299</cda>
      <alpha_stall>1.5</alpha_stall>
      <cla_stall>-3.85</cla_stall>
      <cda_stall>-0.9233984055</cda_stall>
      <area>0.002</area>
      <air_density>1000</air_density>

      <cp>0.027815 -0.001047 0.0054</cp>
      <forward>0.00002 0.2049 -0.0575</forward>
      <upward>-0.01619 -0.07389 -0.10235</upward>
      <link_name>thruster4</link_name>
    </plugin>

    <plugin name='prop4_blade_3' filename='libLiftDragPlugin.so'>
      <a0>0.4</a0>
      <cla>4.752798721</cla>
      <cda>0.6417112299</cda>
      <alpha_stall>1.5</alpha_stall>
      <cla_stall>-3.85</cla_stall>
      <cda_stall>-0.9233984055</cda_stall>
      <area>0.002</area>
      <air_density>1000</air_density>

      <cp>-0.014814 -0.023565 0.0054</cp>
      <forward>0.17744 -0.10247 -0.05749</forward>
      <upward>-0.0559 0.05097 -0.10235</upward>
      <link_name>thruster4</link_name>
    </plugin>

    <plugin name='prop5_blade_1' filename='libLiftDragPlugin.so'>
      <a0>0.08727</a0>
      <cla>5.418</cla>
      <cda>0.0</cda>
      <alpha_stall>0.3368</alpha_stall>
      <cla_stall>0.0</cla_stall>
      <cda_stall>0.0</cda_stall>
      <area>0.002</area>
      <air_density>1000</air_density>

      <cp>-0.015 0.024 0.005</cp>
      <forward>0.04 0.021 -0.023</forward>
      <upward>-0.019 -0.017 -0.034</upward>
      <link_name>thruster5</link_name>
    </plugin>

    <plugin name='prop5_blade_2' filename='libLiftDragPlugin.so'>
      <a0>0.4</a0>
      <cla>4.752798721</cla>
      <cda>0.6417112299</cda>
      <alpha_stall>1.5</alpha_stall>
      <cla_stall>-3.85</cla_stall>
      <cda_stall>-0.9233984055</cda_stall>
      <area>0.002</area>
      <air_density>1000</air_density>

      <cp>-0.013 -0.025 0.005</cp>
      <forward>-0.038 0.023 -0.023</forward>
      <upward>0.024 -0.008 -0.034</upward>
      <link_name>thruster5</link_name>
    </plugin>

    <plugin name='prop5_blade_3' filename='libLiftDragPlugin.so'>
      <a0>0.4</a0>
      <cla>4.752798721</cla>
      <cda>0.6417112299</cda>
      <alpha_stall>1.5</alpha_stall>
      <cla_stall>-3.85</cla_stall>
      <cda_stall>-0.9233984055</cda_stall>
      <area>0.002</area>
      <air_density>1000</air_density>

      <cp>0.028 0.001 0.005</cp>
      <forward>-0.001 -0.045 -0.023</forward>
      <upward>-0.005 0.025 -0.034</upward>
      <link_name>thruster5</link_name>
    </plugin>

    <plugin name='prop6_blade_1' filename='libLiftDragPlugin.so'>
      <a0>0.08727</a0>
      <cla>5.418</cla>
      <cda>0.0</cda>
      <alpha_stall>0.3368</alpha_stall>
      <cla_stall>0.0</cla_stall>
      <cda_stall>0.0</cda_stall>
      <area>0.002</area>
      <air_density>1000</air_density>

      <cp>-0.013001 0.024612 0.0054</cp>
      <forward>-0.17746 -0.10243 -0.0575</forward>
      <upward>0.07209 0.02292 -0.10235</upward>
      <link_name>thruster6</link_name>
    </plugin>

    <plugin name='prop6_blade_2' filename='libLiftDragPlugin.so'>
      <a0>0.4</a0>
      <cla>4.752798721</cla>
      <cda>0.6417112299</cda>
      <alpha_stall>1.5</alpha_stall>
      <cla_stall>-3.85</cla_stall>
      <cda_stall>-0.9233984055</cda_stall>
      <area>0.002</area>
      <air_density>1000</air_density>

      <cp>0.027815 -0.001047 0.0054</cp>
      <forward>0.00002 0.2049 -0.0575</forward>
      <upward>-0.01619 -0.07389 -0.10235</upward>
      <link_name>thruster6</link_name>
    </plugin>

    <plugin name='prop6_blade_3' filename='libLiftDragPlugin.so'>
      <a0>0.4</a0>
      <cla>4.752798721</cla>
      <cda>0.6417112299</cda>
      <alpha_stall>1.5</alpha_stall>
      <cla_stall>-3.85</cla_stall>
      <cda_stall>-0.9233984055</cda_stall>
      <area>0.002</area>
      <air_density>1000</air_density>

      <cp>-0.014814 -0.023565 0.0054</cp>
      <forward>0.17744 -0.10247 -0.05749</forward>
      <upward>-0.0559 0.05097 -0.10235</upward>
      <link_name>thruster6</link_name>
    </plugin>


    <allow_auto_disable>1</allow_auto_disable>

    <plugin name="ArduPilotPlugin" filename="libArduPilotPlugin.so">
      <fdm_addr>127.0.0.1</fdm_addr>
      <fdm_port_in>9002</fdm_port_in>
      <fdm_port_out>9003</fdm_port_out>-->
      <imuName>BlueRov2::base_link::imu_sensor</imuName>
      <connectionTimeoutMaxCount>5</connectionTimeoutMaxCount>

      <!--
        incoming control command [0, 1]
        so offset it by -0.5 to get [-0.5, 0.5].
        multiplier = 102
        Positive thrust = 51
        Negative thrust = -41
      -->
        <control channel="0">
          <type>VELOCITY</type>
          <offset>-0.5</offset>
          <p_gain>1</p_gain>
          <i_gain>0</i_gain>
          <d_gain>0</d_gain>
          <i_max>0</i_max>
          <i_min>0</i_min>
          <cmd_max>51</cmd_max>
          <cmd_min>-40</cmd_min>
          <jointName>BlueRov2::thruster1_joint</jointName>
          <multiplier>102</multiplier>
        </control>

        <control channel="1">
          <type>VELOCITY</type>
          <offset>-0.5</offset>
          <p_gain>1</p_gain>
          <i_gain>0</i_gain>
          <d_gain>0</d_gain>
          <i_max>0</i_max>
          <i_min>0</i_min>
          <cmd_max>51</cmd_max>
          <cmd_min>-40</cmd_min>
          <jointName>BlueRov2::thruster2_joint</jointName>
          <multiplier>102</multiplier>
        </control>

        <control channel="2">
          <type>VELOCITY</type>
          <offset>-0.5</offset>
          <p_gain>1</p_gain>
          <i_gain>0</i_gain>
          <d_gain>0</d_gain>
          <i_max>0</i_max>
          <i_min>0</i_min>
          <cmd_max>51</cmd_max>
          <cmd_min>-40</cmd_min>
          <jointName>BlueRov2::thruster3_joint</jointName>
          <multiplier>102</multiplier>
        </control>

        <control channel="3">
          <type>VELOCITY</type>
          <offset>-0.5</offset>
          <p_gain>1</p_gain>
          <i_gain>0</i_gain>
          <d_gain>0</d_gain>
          <i_max>0</i_max>
          <i_min>0</i_min>
          <cmd_max>51</cmd_max>
          <cmd_min>-40</cmd_min>
          <jointName>BlueRov2::thruster4_joint</jointName>
          <multiplier>102</multiplier>
        </control>


        <control channel="4">
          <type>VELOCITY</type>
          <offset>-0.5</offset>
          <p_gain>1</p_gain>
          <i_gain>0</i_gain>
          <d_gain>0</d_gain>
          <i_max>0</i_max>
          <i_min>0</i_min>
          <cmd_max>51</cmd_max>
          <cmd_min>-40</cmd_min>
          <jointName>BlueRov2::thruster5_joint</jointName>
          <multiplier>102</multiplier>

        </control>

        <control channel="5">
          <type>VELOCITY</type>
          <offset>-0.5</offset>
          <p_gain>1</p_gain>
          <i_gain>0</i_gain>
          <d_gain>0</d_gain>
          <i_max>0</i_max>
          <i_min>0</i_min>
          <cmd_max>51</cmd_max>
          <cmd_min>-40</cmd_min>
          <jointName>BlueRov2::thruster6_joint</jointName>
          <multiplier>102</multiplier>
        </control>
    </plugin>

    <plugin name="freebuoyancy_gazebo" filename="libfreebuoyancy_gazebo.so">
      <descriptionParam>robot_description</descriptionParam>
      <fluidTopic>current</fluidTopic>
      <alwaysOn>true</alwaysOn>
      <surface>0 0 0</surface>
      <updateRate>.001</updateRate>

      <link name="base_link">
        <buoyancy>
          <compensation>1.01</compensation>
          <origin xyz= "0.16 0.2 -0.125"/>
        </buoyancy>
      </link>
    </plugin>
  </model>
</sdf>
